Traceback (most recent call last):
  File "/home/sie/miniconda3/envs/env1/lib/python3.11/site-packages/jupyter_cache/executors/utils.py", line 58, in single_nb_execution
    executenb(
  File "/home/sie/miniconda3/envs/env1/lib/python3.11/site-packages/nbclient/client.py", line 1305, in execute
    return NotebookClient(nb=nb, resources=resources, km=km, **kwargs).execute()
           ^^^^^^^^^^^^^^^^^^^^^^^^^^^^^^^^^^^^^^^^^^^^^^^^^^^^^^^^^^^^^^^^^^^^^
  File "/home/sie/miniconda3/envs/env1/lib/python3.11/site-packages/jupyter_core/utils/__init__.py", line 173, in wrapped
    return loop.run_until_complete(inner)
           ^^^^^^^^^^^^^^^^^^^^^^^^^^^^^^
  File "/home/sie/miniconda3/envs/env1/lib/python3.11/asyncio/base_events.py", line 653, in run_until_complete
    return future.result()
           ^^^^^^^^^^^^^^^
  File "/home/sie/miniconda3/envs/env1/lib/python3.11/site-packages/nbclient/client.py", line 705, in async_execute
    await self.async_execute_cell(
  File "/home/sie/miniconda3/envs/env1/lib/python3.11/site-packages/nbclient/client.py", line 1058, in async_execute_cell
    await self._check_raise_for_error(cell, cell_index, exec_reply)
  File "/home/sie/miniconda3/envs/env1/lib/python3.11/site-packages/nbclient/client.py", line 914, in _check_raise_for_error
    raise CellExecutionError.from_cell_and_msg(cell, exec_reply_content)
nbclient.exceptions.CellExecutionError: An error occurred while executing the following cell:
------------------
model = keras.Sequential([
    keras.layers.Dense(10, input_shape=[1]),
    keras.layers.Dense(1)
])

model.compile(loss = 'mae',
              optimizer = 'SGD',
              metrics = 'mae' )

model.fit(X, y, epochs=5)
------------------


[0;31m---------------------------------------------------------------------------[0m
[0;31mNameError[0m                                 Traceback (most recent call last)
Cell [0;32mIn[2], line 1[0m
[0;32m----> 1[0m model [38;5;241m=[39m keras[38;5;241m.[39mSequential([
[1;32m      2[0m     keras[38;5;241m.[39mlayers[38;5;241m.[39mDense([38;5;241m10[39m, input_shape[38;5;241m=[39m[[38;5;241m1[39m]),
[1;32m      3[0m     keras[38;5;241m.[39mlayers[38;5;241m.[39mDense([38;5;241m1[39m)
[1;32m      4[0m ])
[1;32m      6[0m model[38;5;241m.[39mcompile(loss [38;5;241m=[39m [38;5;124m'[39m[38;5;124mmae[39m[38;5;124m'[39m,
[1;32m      7[0m               optimizer [38;5;241m=[39m [38;5;124m'[39m[38;5;124mSGD[39m[38;5;124m'[39m,
[1;32m      8[0m               metrics [38;5;241m=[39m [38;5;124m'[39m[38;5;124mmae[39m[38;5;124m'[39m )
[1;32m     10[0m model[38;5;241m.[39mfit(X, y, epochs[38;5;241m=[39m[38;5;241m5[39m)

[0;31mNameError[0m: name 'keras' is not defined

